<?xml version="1.0" encoding="utf-8"?>
<!-- =================================================================================== -->
<!-- |    This document was autogenerated by xacro from neobotix_base.urdf.xacro       | -->
<!-- |    EDITING THIS FILE BY HAND IS NOT RECOMMENDED                                 | -->
<!-- =================================================================================== -->
<robot name="neobotix_base" xmlns:controller="http://playerstage.sourceforge.net/gazebo/xmlschema/#controller" xmlns:interface="http://playerstage.sourceforge.net/gazebo/xmlschema/#interface" xmlns:sensor="http://playerstage.sourceforge.net/gazebo/xmlschema/#sensor">
  <material name="DarkGrey">
    <color rgba="0.3 0.3 0.3 1.0"/>
  </material>
  <material name="Black">
    <color rgba="0 0 0 1.0"/>
  </material>
  <material name="Orange">
    <color rgba="1.0 0.487 0 1.0"/>
  </material>
  <material name="Silver">
    <color rgba="1.0 1.0 1.0 1.0"/>
  </material>
  <material name="Grey">
    <color rgba="0.7 0.7 0.7 1.0"/>
  </material>
  <material name="Blue">
    <color rgba="0.0 0.0 0.8 1.0"/>
  </material>
  <material name="HandGray">
    <color rgba="0.953 0.996 0.694 1.0"/>
  </material>
  <material name="SickBlue">
    <color rgba="0.3058 0.5921 0.7294 1.0"/>
  </material>
  <!-- Geometric properties of the platform and sensors -->
  <!-- Transformation from chassis to Kinect on pole (faily accurate)
  <xacro:property name="kinect_parent_name" value="chassis"/>
  <xacro:property name="cal_kinect_x"       value="-0.23"/>
  <xacro:property name="cal_kinect_y"       value="-0.260" />
  <xacro:property name="cal_kinect_z"       value="${1.485-0.055}" />
  <xacro:property name="cal_kinect_roll"    value="0" />
  <xacro:property name="cal_kinect_pitch"   value="0.48" />
  <xacro:property name="cal_kinect_yaw"     value="0" /> -->
  <!-- box gripper 
  <xacro:property name="cal_lwr_to_gripper_xyz" value="0 0 0.095" />
  <xacro:property name="cal_lwr_to_gripper_rpy" value="0 0 1.570796327" /> 
  -->
  <link name="base_link">
    <!-- base_link -->
    <inertial>
      <mass value="170.0"/>
      <origin rpy="0 0 0" xyz="0 0 0.15"/>
      <inertia ixx="0.6278896875" ixy="0" ixz="0" iyy="7.76125171875" iyz="0" izz="7.43249296875"/>
    </inertial>
    <visual>
      <origin rpy="0 0 0" xyz="0 0 0.075"/>
      <geometry>
        <mesh filename="package://neo_description/meshes/neo_mp655/neobotix_mp655.dae"/>
      </geometry>
      <material name="Silver"/>
    </visual>
    <collision>
      <origin rpy="0 0 0" xyz="0 0 0.2805"/>
      <geometry>
        <box size="0.68 0.6 0.42"/>
      </geometry>
    </collision>
  </link>
  <gazebo reference="base_link">
    <material value="kimp.material"/>
  </gazebo>
  <!-- base_footprint is a fictitious link(frame) that is on the ground 
         right below base_link origin, navigation stack depends on this frame -->
  <link name="base_footprint"/>
  <joint name="base_footprint_joint" type="fixed">
    <origin rpy="0 0 0" xyz="0 0 0"/>
    <child link="base_link"/>
    <parent link="base_footprint"/>
  </joint>
  <joint name="left_wheel_joint" type="continuous">
    <origin rpy="0 0 1.57079632679" xyz="0 0.3255 0.075"/>
    <parent link="base_link"/>
    <child link="left_wheel_link"/>
  </joint>
  <link name="left_wheel_link">
    <inertial>
      <mass value="3.0"/>
      <origin rpy="0 0 0" xyz="0 0 0"/>
      <inertia ixx="0.004525" ixy="0" ixz="0" iyy="0.0084375" iyz="0" izz="0.004525"/>
    </inertial>
    <collision>
      <origin rpy="0 -1.57079632679 0" xyz="0 0 0"/>
      <geometry>
        <cylinder length="0.035" radius="0.07575"/>
      </geometry>
    </collision>
  </link>
  <gazebo reference="left_wheel_link">
    <material value="Gazebo/Black"/>
    <mu1>10.0</mu1>
    <mu2>10.0</mu2>
    <kp>500000.0</kp>
    <kd>10.0</kd>
    <minDepth>0.001</minDepth>
    <maxVel>0.1</maxVel>
    <fdir1>1 0 0</fdir1>
  </gazebo>
  <joint name="right_wheel_joint" type="continuous">
    <origin rpy="0 0 -1.57079632679" xyz="0 -0.3255 0.075"/>
    <parent link="base_link"/>
    <child link="right_wheel_link"/>
  </joint>
  <link name="right_wheel_link">
    <inertial>
      <mass value="3.0"/>
      <origin rpy="0 0 0" xyz="0 0 0"/>
      <inertia ixx="0.004525" ixy="0" ixz="0" iyy="0.0084375" iyz="0" izz="0.004525"/>
    </inertial>
    <collision>
      <origin rpy="0 1.57079632679 0" xyz="0 0 0"/>
      <geometry>
        <cylinder length="0.035" radius="0.07575"/>
      </geometry>
    </collision>
  </link>
  <gazebo reference="right_wheel_link">
    <material value="Gazebo/Black"/>
    <mu1>10.0</mu1>
    <mu2>10.0</mu2>
    <kp>500000.0</kp>
    <kd>10.0</kd>
    <minDepth>0.001</minDepth>
    <maxVel>0.1</maxVel>
    <fdir1>1 0 0</fdir1>
  </gazebo>
  <joint name="front_right_caster_joint" type="fixed">
    <origin rpy="0 0 0" xyz="0.28 -0.24 0.075"/>
    <parent link="base_link"/>
    <child link="front_right_caster_link"/>
  </joint>
  <link name="front_right_caster_link">
    <inertial>
      <mass value="0.5"/>
      <origin rpy="0 0 0" xyz="0 0 0"/>
      <inertia ixx="0.001" ixy="0" ixz="0" iyy="0.001" iyz="0" izz="0.001"/>
    </inertial>
    <collision>
      <origin rpy="0 0 0" xyz="0 0 0"/>
      <geometry>
        <sphere radius="0.075 * 0.99"/>
      </geometry>
    </collision>
  </link>
  <gazebo reference="front_right_caster_link">
    <material value="Gazebo/Black"/>
    <mu1>0.01</mu1>
    <mu2>0.01</mu2>
    <kp>1000000.0</kp>
    <kd>100.0</kd>
    <minDepth>0.001</minDepth>
    <!-- Minimum allowable depth before contact correction impulse is applied -->
    <maxVel>1.0</maxVel>
    <!-- <slip1></slip1> -->
    <!-- <slip2></slip2> -->
    <!-- <turnGravityOff>false</turnGravityOff> -->
  </gazebo>
  <joint name="front_left_caster_joint" type="fixed">
    <origin rpy="0 0 0" xyz="0.28 0.24 0.075"/>
    <parent link="base_link"/>
    <child link="front_left_caster_link"/>
  </joint>
  <link name="front_left_caster_link">
    <inertial>
      <mass value="0.5"/>
      <origin rpy="0 0 0" xyz="0 0 0"/>
      <inertia ixx="0.001" ixy="0" ixz="0" iyy="0.001" iyz="0" izz="0.001"/>
    </inertial>
    <collision>
      <origin rpy="0 0 0" xyz="0 0 0"/>
      <geometry>
        <sphere radius="0.075 * 0.99"/>
      </geometry>
    </collision>
  </link>
  <gazebo reference="front_left_caster_link">
    <material value="Gazebo/Black"/>
    <mu1>0.01</mu1>
    <mu2>0.01</mu2>
    <kp>1000000.0</kp>
    <kd>100.0</kd>
    <minDepth>0.001</minDepth>
    <!-- Minimum allowable depth before contact correction impulse is applied -->
    <maxVel>1.0</maxVel>
    <!-- <slip1></slip1> -->
    <!-- <slip2></slip2> -->
    <!-- <turnGravityOff>false</turnGravityOff> -->
  </gazebo>
  <joint name="rear_caster_joint" type="fixed">
    <origin rpy="0 0 0" xyz="-0.28 0 0.075"/>
    <parent link="base_link"/>
    <child link="rear_caster_link"/>
  </joint>
  <link name="rear_caster_link">
    <inertial>
      <mass value="0.5"/>
      <origin rpy="0 0 0" xyz="0 0 0"/>
      <inertia ixx="0.001" ixy="0" ixz="0" iyy="0.001" iyz="0" izz="0.001"/>
    </inertial>
    <collision>
      <origin rpy="0 0 0" xyz="0 0 0"/>
      <geometry>
        <sphere radius="0.075 * 0.99"/>
      </geometry>
    </collision>
  </link>
  <gazebo reference="rear_caster_link">
    <material value="Gazebo/Black"/>
    <mu1>0.01</mu1>
    <mu2>0.01</mu2>
    <kp>1000000.0</kp>
    <kd>100.0</kd>
    <minDepth>0.001</minDepth>
    <!-- Minimum allowable depth before contact correction impulse is applied -->
    <maxVel>1.0</maxVel>
    <!-- <slip1></slip1> -->
    <!-- <slip2></slip2> -->
    <!-- <turnGravityOff>false</turnGravityOff> -->
  </gazebo>
  <!-- //////////////////////////////////////////////////////////////////// -->
  <!-- Five ultrasonic sensors -->
  <!-- 
    <ultrasonic_sensor parent="${name}" type="US" location="frontR">
       <origin xyz="0.357 -0.160 0.377" rpy="0 -0.52 0"/>
    </ultrasonic_sensor>
    <ultrasonic_sensor parent="${name}" type="US" location="frontM">
       <origin xyz="0.357 0 0.377" rpy="0 -0.52 0"/>
    </ultrasonic_sensor>
    <ultrasonic_sensor parent="${name}" type="US" location="frontL">
       <origin xyz="0.357 0.160 0.377" rpy="0 -0.52 0"/>
    </ultrasonic_sensor>
    <ultrasonic_sensor parent="${name}" type="US" location="rearR">
       <origin xyz="-0.357 -0.115 0.374" rpy="${M_PI} -2.62 0"/>
    </ultrasonic_sensor>
    <ultrasonic_sensor parent="${name}" type="US" location="rearL">
       <origin xyz="-0.357 0.115 0.374" rpy="${M_PI} -2.62 0"/>
    </ultrasonic_sensor> 
    -->
  <!-- CONTROLLERS (as seen in erratic_base.xacro -->
  <gazebo>
    <controller:diffdrive_plugin name="differential_drive_controller" plugin="libdiffdrive_plugin.so">
      <alwaysOn>true</alwaysOn>
      <update>100</update>
      <updateRate>100.0</updateRate>
      <leftJoint>right_wheel_joint</leftJoint>
      <rightJoint>left_wheel_joint</rightJoint>
      <wheelSeparation>0.651</wheelSeparation>
      <wheelDiameter>0.15</wheelDiameter>
      <torque>5</torque>
      <interface:position name="position_iface_0"/>
      <topicName>cmd_vel</topicName>
    </controller:diffdrive_plugin>
    <controller:gazebo_ros_p3d name="p3d_base_controller" plugin="libgazebo_ros_p3d.so">
      <alwaysOn>true</alwaysOn>
      <updateRate>100.0</updateRate>
      <bodyName>base_link</bodyName>
      <topicName>base_pose_ground_truth</topicName>
      <gaussianNoise>0.01</gaussianNoise>
      <frameName>map</frameName>
      <xyzOffsets>0 0 0</xyzOffsets>
      <rpyOffsets>0 0 0</rpyOffsets>
      <interface:position name="p3d_base_position"/>
    </controller:gazebo_ros_p3d>
    <!--canonicalBody>base_footprint</canonicalBody-->
    <!-- this publishes empty joint_states due to no transmission, but
             triggering robot_state_publisher to publish tf between fixed joints in erratic,
             (e.g. base_laser_link for the base_scan frame) -->
    <controller:gazebo_ros_controller_manager name="gazebo_ros_controller_manager" plugin="libgazebo_ros_controller_manager.so">
      <alwaysOn>true</alwaysOn>
      <updateRate>100.0</updateRate>
      <interface:audio name="gazebo_ros_controller_manager_dummy_iface"/>
    </controller:gazebo_ros_controller_manager>
  </gazebo>
  <joint name="laserfront_joint" type="fixed">
    <axis xyz="0 1 0"/>
    <origin rpy="0.0 0.0 0.0" xyz="0.377 0.0 0.16"/>
    <parent link="base_link"/>
    <child link="laserfront_link"/>
  </joint>
  <link name="laserfront_link" type="laser">
    <inertial>
      <mass value="0.001"/>
      <origin rpy="0 0 0" xyz="0 0 0"/>
      <inertia ixx="0.0001" ixy="0" ixz="0" iyy="0.000001" iyz="0" izz="0.0001"/>
    </inertial>
    <visual>
      <origin rpy="0 0 0" xyz="0 0 0"/>
      <geometry>
        <mesh filename="package://neo_description/meshes/neo_mp655/sick_s300.dae"/>
      </geometry>
    </visual>
    <collision>
      <origin rpy="0 0 0" xyz="0 0 0"/>
      <geometry>
        <box size=".1 .1 .1"/>
      </geometry>
    </collision>
  </link>
  <gazebo reference="laserfront_link">
    <sensor:ray name="laserfront">
      <rayCount>541</rayCount>
      <rangeCount>541</rangeCount>
      <laserCount>1</laserCount>
      <origin>0.0 0.0 0.0</origin>
      <displayRays>false</displayRays>
      <minAngle>-95.1592356688</minAngle>
      <maxAngle>95.1592356688</maxAngle>
      <minRange>0.05</minRange>
      <maxRange>30.0</maxRange>
      <resRange>0.03</resRange>
      <updateRate>5</updateRate>
      <controller:gazebo_ros_laser name="gazebo_ros_laserfront_controller" plugin="libgazebo_ros_laser.so">
        <gaussianNoise>0.005</gaussianNoise>
        <alwaysOn>true</alwaysOn>
        <updateRate>5</updateRate>
        <topicName>scan_front/scan</topicName>
        <frameName>/laserfront_link</frameName>
        <interface:laser name="gazebo_ros_laserfront_iface"/>
      </controller:gazebo_ros_laser>
    </sensor:ray>
  </gazebo>
  <joint name="laserback_joint" type="fixed">
    <axis xyz="0 1 0"/>
    <origin rpy="0.0 0.0 3.141592654" xyz="-0.377 0.0 0.16"/>
    <parent link="base_link"/>
    <child link="laserback_link"/>
  </joint>
  <link name="laserback_link" type="laser">
    <inertial>
      <mass value="0.001"/>
      <origin rpy="0 0 0" xyz="0 0 0"/>
      <inertia ixx="0.0001" ixy="0" ixz="0" iyy="0.000001" iyz="0" izz="0.0001"/>
    </inertial>
    <visual>
      <origin rpy="0 0 0" xyz="0 0 0"/>
      <geometry>
        <mesh filename="package://neo_description/meshes/neo_mp655/sick_s300.dae"/>
      </geometry>
    </visual>
    <collision>
      <origin rpy="0 0 0" xyz="0 0 0"/>
      <geometry>
        <box size=".1 .1 .1"/>
      </geometry>
    </collision>
  </link>
  <gazebo reference="laserback_link">
    <sensor:ray name="laserback">
      <rayCount>541</rayCount>
      <rangeCount>541</rangeCount>
      <laserCount>1</laserCount>
      <origin>0.0 0.0 0.0</origin>
      <displayRays>false</displayRays>
      <minAngle>-135.068473949</minAngle>
      <maxAngle>424.33012549</maxAngle>
      <minRange>0.05</minRange>
      <maxRange>30.0</maxRange>
      <resRange>0.03</resRange>
      <updateRate>5</updateRate>
      <controller:gazebo_ros_laser name="gazebo_ros_laserback_controller" plugin="libgazebo_ros_laser.so">
        <gaussianNoise>0.005</gaussianNoise>
        <alwaysOn>true</alwaysOn>
        <updateRate>5</updateRate>
        <topicName>scan_back/scan</topicName>
        <frameName>/laserback_link</frameName>
        <interface:laser name="gazebo_ros_laserback_iface"/>
      </controller:gazebo_ros_laser>
    </sensor:ray>
  </gazebo>
</robot>

